INFO:services.cache_service:Connected to Redis at redis://localhost:6379/0
INFO:services.google_vision_service:ü§ñ Gemini initialized with model: gemini-2.0-flash
INFO:services.archive_photo_service:üèõÔ∏è Archive Photo Service initialized with 3 photos
INFO:services.google_vision_service:üèõÔ∏è Archive service integrated into Google Vision
WARNING:services.google_vision_service:Google Cloud Vision credentials not found
ERROR:services.image_database_service:Database connection failed: (psycopg2.OperationalError) connection to server at "localhost" (127.0.0.1), port 5432 failed: FATAL:  password authentication failed for user "postgres"
connection to server at "localhost" (127.0.0.1), port 5432 failed: FATAL:  password authentication failed for user "postgres"

(Background on this error at: https://sqlalche.me/e/20/e3q8)
ERROR:services.image_database_service:Database connection failed: (psycopg2.OperationalError) connection to server at "localhost" (127.0.0.1), port 5432 failed: FATAL:  password authentication failed for user "postgres"
connection to server at "localhost" (127.0.0.1), port 5432 failed: FATAL:  password authentication failed for user "postgres"

(Background on this error at: https://sqlalche.me/e/20/e3q8)
WARNING:services.mistral_ai_service:MISTRAL_API_KEY not found in environment variables
INFO:routes.geo_api:Geo services initialized successfully
/home/denis/Documents/Hackathon_2025/geo_locator/backend/venv/lib/python3.12/site-packages/ultralytics/nn/tasks.py:567: FutureWarning: You are using `torch.load` with `weights_only=False` (the current default value), which uses the default pickle module implicitly. It is possible to construct malicious pickle data which will execute arbitrary code during unpickling (See https://github.com/pytorch/pytorch/blob/main/SECURITY.md#untrusted-models for more details). In a future release, the default value for `weights_only` will be flipped to `True`. This limits the functions that could be executed during unpickling. Arbitrary objects will no longer be allowed to be loaded via this mode unless they are explicitly allowlisted by the user via `torch.serialization.add_safe_globals`. We recommend you start setting `weights_only=True` for any use case where you don't have full control of the loaded file. Please open an issue on GitHub for any issues related to this experimental feature.
  return torch.load(file, map_location='cpu'), file  # load
INFO:services.yolo_violation_detector:Loaded pretrained YOLOv8n model
INFO:services.yolo_violation_detector:YOLOv8 Object Detector initialized on cpu
INFO:services.coordinate_detector:‚úÖ YOLO detector initialized
ERROR:services.image_database_service:Database connection failed: (psycopg2.OperationalError) connection to server at "localhost" (127.0.0.1), port 5432 failed: FATAL:  password authentication failed for user "postgres"
connection to server at "localhost" (127.0.0.1), port 5432 failed: FATAL:  password authentication failed for user "postgres"

(Background on this error at: https://sqlalche.me/e/20/e3q8)
INFO:services.coordinate_detector:‚úÖ API services initialized (Yandex, 2GIS, Roscosmos)
INFO:services.google_vision_service:ü§ñ Gemini initialized with model: gemini-2.0-flash
INFO:services.archive_photo_service:üèõÔ∏è Archive Photo Service initialized with 3 photos
INFO:services.google_vision_service:üèõÔ∏è Archive service integrated into Google Vision
WARNING:services.google_vision_service:Google Cloud Vision credentials not found
INFO:services.coordinate_detector:‚úÖ Google Vision service initialized
INFO:services.archive_photo_service:üèõÔ∏è Archive Photo Service initialized with 3 photos
INFO:services.coordinate_detector:üèõÔ∏è Archive Photo service initialized
INFO:services.coordinate_detector:Coordinate Detector initialized
INFO:services.yolo_violation_detector:Loaded pretrained YOLOv8n model
INFO:services.yolo_violation_detector:YOLOv8 Object Detector initialized on cpu
INFO:services.coordinate_detector:‚úÖ YOLO detector initialized
ERROR:services.image_database_service:Database connection failed: (psycopg2.OperationalError) connection to server at "localhost" (127.0.0.1), port 5432 failed: FATAL:  password authentication failed for user "postgres"
connection to server at "localhost" (127.0.0.1), port 5432 failed: FATAL:  password authentication failed for user "postgres"

(Background on this error at: https://sqlalche.me/e/20/e3q8)
INFO:services.coordinate_detector:‚úÖ API services initialized (Yandex, 2GIS, Roscosmos)
INFO:services.google_vision_service:ü§ñ Gemini initialized with model: gemini-2.0-flash
INFO:services.archive_photo_service:üèõÔ∏è Archive Photo Service initialized with 3 photos
INFO:services.google_vision_service:üèõÔ∏è Archive service integrated into Google Vision
WARNING:services.google_vision_service:Google Cloud Vision credentials not found
INFO:services.coordinate_detector:‚úÖ Google Vision service initialized
INFO:services.archive_photo_service:üèõÔ∏è Archive Photo Service initialized with 3 photos
INFO:services.coordinate_detector:üèõÔ∏è Archive Photo service initialized
INFO:services.coordinate_detector:Coordinate Detector initialized
INFO:services.video_coordinate_detector:Video Coordinate Detector initialized
‚úÖ Maps API registered successfully
Warning: YOLOViolationDetector not available: cannot import name 'YOLOViolationDetector' from 'services.yolo_violation_detector' (/home/denis/Documents/Hackathon_2025/geo_locator/backend/services/yolo_violation_detector.py)
‚úÖ Violation API registered successfully
‚úÖ Geo API registered successfully
‚úÖ Cache API registered successfully
‚úÖ Rosreestr API registered successfully
‚úÖ OpenStreetMap API registered successfully
‚ùå Sentinel API registration failed: attempted relative import beyond top-level package
‚úÖ Satellite API registered successfully
‚úÖ OCR API registered successfully
‚úÖ Notification API registered successfully
‚úÖ Coordinate API registered successfully
üöÄ Starting Geo Locator Backend (Local Development)
==================================================
‚úÖ PostgreSQL connection successful
‚úÖ Redis connection successful
‚úÖ Database tables created successfully

üéâ All checks passed! Starting Flask development server...
üìç Backend will be available at: http://localhost:5001
üìç API endpoints at: http://localhost:5001/api/

Press Ctrl+C to stop the server
==================================================
 * Serving Flask app 'app'
 * Debug mode: on
INFO:werkzeug:[31m[1mWARNING: This is a development server. Do not use it in a production deployment. Use a production WSGI server instead.[0m
 * Running on all addresses (0.0.0.0)
 * Running on http://127.0.0.1:5001
 * Running on http://10.0.85.1:5001
INFO:werkzeug:[33mPress CTRL+C to quit[0m
INFO:werkzeug: * Restarting with stat
INFO:services.cache_service:Connected to Redis at redis://localhost:6379/0
INFO:services.google_vision_service:ü§ñ Gemini initialized with model: gemini-2.0-flash
INFO:services.archive_photo_service:üèõÔ∏è Archive Photo Service initialized with 3 photos
INFO:services.google_vision_service:üèõÔ∏è Archive service integrated into Google Vision
WARNING:services.google_vision_service:Google Cloud Vision credentials not found
ERROR:services.image_database_service:Database connection failed: (psycopg2.OperationalError) connection to server at "localhost" (127.0.0.1), port 5432 failed: FATAL:  password authentication failed for user "postgres"
connection to server at "localhost" (127.0.0.1), port 5432 failed: FATAL:  password authentication failed for user "postgres"

(Background on this error at: https://sqlalche.me/e/20/e3q8)
ERROR:services.image_database_service:Database connection failed: (psycopg2.OperationalError) connection to server at "localhost" (127.0.0.1), port 5432 failed: FATAL:  password authentication failed for user "postgres"
connection to server at "localhost" (127.0.0.1), port 5432 failed: FATAL:  password authentication failed for user "postgres"

(Background on this error at: https://sqlalche.me/e/20/e3q8)
WARNING:services.mistral_ai_service:MISTRAL_API_KEY not found in environment variables
INFO:routes.geo_api:Geo services initialized successfully
/home/denis/Documents/Hackathon_2025/geo_locator/backend/venv/lib/python3.12/site-packages/ultralytics/nn/tasks.py:567: FutureWarning: You are using `torch.load` with `weights_only=False` (the current default value), which uses the default pickle module implicitly. It is possible to construct malicious pickle data which will execute arbitrary code during unpickling (See https://github.com/pytorch/pytorch/blob/main/SECURITY.md#untrusted-models for more details). In a future release, the default value for `weights_only` will be flipped to `True`. This limits the functions that could be executed during unpickling. Arbitrary objects will no longer be allowed to be loaded via this mode unless they are explicitly allowlisted by the user via `torch.serialization.add_safe_globals`. We recommend you start setting `weights_only=True` for any use case where you don't have full control of the loaded file. Please open an issue on GitHub for any issues related to this experimental feature.
  return torch.load(file, map_location='cpu'), file  # load
INFO:services.yolo_violation_detector:Loaded pretrained YOLOv8n model
INFO:services.yolo_violation_detector:YOLOv8 Object Detector initialized on cpu
INFO:services.coordinate_detector:‚úÖ YOLO detector initialized
ERROR:services.image_database_service:Database connection failed: (psycopg2.OperationalError) connection to server at "localhost" (127.0.0.1), port 5432 failed: FATAL:  password authentication failed for user "postgres"
connection to server at "localhost" (127.0.0.1), port 5432 failed: FATAL:  password authentication failed for user "postgres"

(Background on this error at: https://sqlalche.me/e/20/e3q8)
INFO:services.coordinate_detector:‚úÖ API services initialized (Yandex, 2GIS, Roscosmos)
INFO:services.google_vision_service:ü§ñ Gemini initialized with model: gemini-2.0-flash
INFO:services.archive_photo_service:üèõÔ∏è Archive Photo Service initialized with 3 photos
INFO:services.google_vision_service:üèõÔ∏è Archive service integrated into Google Vision
WARNING:services.google_vision_service:Google Cloud Vision credentials not found
INFO:services.coordinate_detector:‚úÖ Google Vision service initialized
INFO:services.archive_photo_service:üèõÔ∏è Archive Photo Service initialized with 3 photos
INFO:services.coordinate_detector:üèõÔ∏è Archive Photo service initialized
INFO:services.coordinate_detector:Coordinate Detector initialized
INFO:services.yolo_violation_detector:Loaded pretrained YOLOv8n model
INFO:services.yolo_violation_detector:YOLOv8 Object Detector initialized on cpu
INFO:services.coordinate_detector:‚úÖ YOLO detector initialized
ERROR:services.image_database_service:Database connection failed: (psycopg2.OperationalError) connection to server at "localhost" (127.0.0.1), port 5432 failed: FATAL:  password authentication failed for user "postgres"
connection to server at "localhost" (127.0.0.1), port 5432 failed: FATAL:  password authentication failed for user "postgres"

(Background on this error at: https://sqlalche.me/e/20/e3q8)
INFO:services.coordinate_detector:‚úÖ API services initialized (Yandex, 2GIS, Roscosmos)
INFO:services.google_vision_service:ü§ñ Gemini initialized with model: gemini-2.0-flash
INFO:services.archive_photo_service:üèõÔ∏è Archive Photo Service initialized with 3 photos
INFO:services.google_vision_service:üèõÔ∏è Archive service integrated into Google Vision
WARNING:services.google_vision_service:Google Cloud Vision credentials not found
INFO:services.coordinate_detector:‚úÖ Google Vision service initialized
INFO:services.archive_photo_service:üèõÔ∏è Archive Photo Service initialized with 3 photos
INFO:services.coordinate_detector:üèõÔ∏è Archive Photo service initialized
INFO:services.coordinate_detector:Coordinate Detector initialized
INFO:services.video_coordinate_detector:Video Coordinate Detector initialized
WARNING:werkzeug: * Debugger is active!
INFO:werkzeug: * Debugger PIN: 111-291-728
INFO:werkzeug:127.0.0.1 - - [11/Sep/2025 17:38:57] "OPTIONS /api/violations/list HTTP/1.1" 200 -
INFO:app:üìä Database - Retrieved 86 violations from database
INFO:werkzeug:127.0.0.1 - - [11/Sep/2025 17:38:58] "GET /api/violations/list HTTP/1.1" 200 -
INFO:app:üìä Database - Retrieved 86 violations from database
INFO:werkzeug:127.0.0.1 - - [11/Sep/2025 17:38:58] "GET /api/violations/list HTTP/1.1" 200 -
INFO:werkzeug:127.0.0.1 - - [11/Sep/2025 17:38:58] "[33mGET /logo192.png HTTP/1.1[0m" 404 -
INFO:werkzeug:127.0.0.1 - - [11/Sep/2025 17:39:15] "OPTIONS /api/coordinates/detect HTTP/1.1" 200 -
ERROR:services.google_vision_service:Gemini API error: 400 User location is not supported for the API use.
WARNING:services.google_vision_service:üåç Gemini API blocked due to location restrictions. Try VPN to US/UK/Canada
INFO:services.coordinate_detector:üó∫Ô∏è Location hint received: '–ú–æ—Å–∫–≤–∞' (type: <class 'str'>, bool: True)
INFO:services.coordinate_detector:üó∫Ô∏è Processing location hint: '–ú–æ—Å–∫–≤–∞'
INFO:services.geo_aggregator_service:Starting geolocation for image: /home/denis/Documents/Hackathon_2025/geo_locator/backend/uploads/coordinates/1krasn_pl2-3797155958.jpg
INFO:services.geo_aggregator_service:Yandex found 1 places
ERROR:services.dgis_service:2GIS search error: HTTPSConnectionPool(host='catalog.api.2gis.com', port=443): Max retries exceeded with url: /3.0/items?key=f05899c8-de48-45b5-b36e-b462c22f61e0&q=%D0%9C%D0%BE%D1%81%D0%BA%D0%B2%D0%B0&page_size=20&fields=items.point%2Citems.adm_div%2Citems.address%2Citems.contact_groups%2Citems.rubrics%2Citems.reviews%2Citems.photos&region_id=1 (Caused by NameResolutionError("<urllib3.connection.HTTPSConnection object at 0x78bc30654f50>: Failed to resolve 'catalog.api.2gis.com' ([Errno -2] Name or service not known)"))
INFO:services.geo_aggregator_service:API results: {'yandex': {'success': True, 'source': 'yandex_maps', 'query': '–ú–æ—Å–∫–≤–∞', 'total_found': 1, 'places': [{'name': '–ú–æ—Å–∫–≤–∞', 'description': '–†–æ—Å—Å–∏—è', 'coordinates': {'latitude': 55.755864, 'longitude': 37.617698}, 'address': '–†–æ—Å—Å–∏—è, –ú–æ—Å–∫–≤–∞', 'category': ['province'], 'phone': [], 'url': '', 'hours': {}, 'precision': 'other', 'type': 'province'}]}, 'dgis': {'success': False}, 'osm': {'success': False}}
INFO:services.geo_aggregator_service:Yandex places found: 1
INFO:services.geo_aggregator_service:All results before aggregation: {'external_apis': {'yandex': {'success': True, 'source': 'yandex_maps', 'query': '–ú–æ—Å–∫–≤–∞', 'total_found': 1, 'places': [{'name': '–ú–æ—Å–∫–≤–∞', 'description': '–†–æ—Å—Å–∏—è', 'coordinates': {'latitude': 55.755864, 'longitude': 37.617698}, 'address': '–†–æ—Å—Å–∏—è, –ú–æ—Å–∫–≤–∞', 'category': ['province'], 'phone': [], 'url': '', 'hours': {}, 'precision': 'other', 'type': 'province'}]}, 'dgis': {'success': False}, 'osm': {'success': False}}}
INFO:services.geo_aggregator_service:External APIs details:
INFO:services.geo_aggregator_service:  yandex: success=True, places_count=1
INFO:services.geo_aggregator_service:    First place coordinates: {'latitude': 55.755864, 'longitude': 37.617698}
INFO:services.geo_aggregator_service:  dgis: success=False, places_count=0
INFO:services.geo_aggregator_service:  osm: success=False, places_count=0
INFO:services.geo_aggregator_service:Added candidate from yandex: {'latitude': 55.755864, 'longitude': 37.617698}
INFO:services.geo_aggregator_service:Final location after aggregation: {'coordinates': {'latitude': 55.755864, 'longitude': 37.617698}, 'source': 'yandex_search', 'weight': 0.7, 'confidence': 0.7, 'place_info': {'name': '–ú–æ—Å–∫–≤–∞', 'description': '–†–æ—Å—Å–∏—è', 'coordinates': {'latitude': 55.755864, 'longitude': 37.617698}, 'address': '–†–æ—Å—Å–∏—è, –ú–æ—Å–∫–≤–∞', 'category': ['province'], 'phone': [], 'url': '', 'hours': {}, 'precision': 'other', 'type': 'province'}}
ERROR:services.image_database_service:Error adding image: 'NoneType' object has no attribute 'query'
ERROR:services.geo_aggregator_service:Error adding image to database: 'NoneType' object has no attribute 'rollback'
INFO:services.geo_aggregator_service:Geolocation completed. Success: True, Confidence: 0.70
INFO:services.coordinate_detector:üó∫Ô∏è Geo result with hint: {'success': True, 'final_location': {'coordinates': {'latitude': 55.755864, 'longitude': 37.617698}, 'source': 'yandex_search', 'weight': 0.7, 'confidence': 0.7, 'place_info': {'name': '–ú–æ—Å–∫–≤–∞', 'description': '–†–æ—Å—Å–∏—è', 'coordinates': {'latitude': 55.755864, 'longitude': 37.617698}, 'address': '–†–æ—Å—Å–∏—è, –ú–æ—Å–∫–≤–∞', 'category': ['province'], 'phone': [], 'url': '', 'hours': {}, 'precision': 'other', 'type': 'province'}}, 'confidence_score': 0.7, 'sources_used': ['yandex_search'], 'all_results': {'external_apis': {'yandex': {'success': True, 'source': 'yandex_maps', 'query': '–ú–æ—Å–∫–≤–∞', 'total_found': 1, 'places': [{'name': '–ú–æ—Å–∫–≤–∞', 'description': '–†–æ—Å—Å–∏—è', 'coordinates': {'latitude': 55.755864, 'longitude': 37.617698}, 'address': '–†–æ—Å—Å–∏—è, –ú–æ—Å–∫–≤–∞', 'category': ['province'], 'phone': [], 'url': '', 'hours': {}, 'precision': 'other', 'type': 'province'}]}, 'dgis': {'success': False}, 'osm': {'success': False}}}, 'recommendations': ['–°—Ä–µ–¥–Ω—è—è —É–≤–µ—Ä–µ–Ω–Ω–æ—Å—Ç—å –≤ —Ä–µ–∑—É–ª—å—Ç–∞—Ç–µ', '–î–ª—è –ø–æ–≤—ã—à–µ–Ω–∏—è —Ç–æ—á–Ω–æ—Å—Ç–∏ –¥–æ–±–∞–≤—å—Ç–µ –æ–ø–∏—Å–∞–Ω–∏–µ –º–µ—Å—Ç–∞']}
INFO:services.coordinate_detector:üó∫Ô∏è Location hint processing successful
INFO:services.coordinate_detector:üèõÔ∏è Archive search - Service available: True
INFO:services.coordinate_detector:üèõÔ∏è Archive search - Searching for similar buildings in archive...
INFO:services.archive_photo_service:üîç Found 0 similar buildings (threshold: 0.75)
INFO:services.coordinate_detector:üèõÔ∏è Archive search - Result: None
INFO:services.coordinate_detector:üèõÔ∏è Archive search - No matches found
INFO:services.coordinate_detector:üìç Coordinate sources: GPS=False, Geo=True, Archive=False
INFO:services.coordinate_detector:üîç Combining coordinate sources:
INFO:services.coordinate_detector:  GPS: None
INFO:services.coordinate_detector:  Geo: {'success': True, 'final_location': {'coordinates': {'latitude': 55.755864, 'longitude': 37.617698}, 'source': 'yandex_search', 'weight': 0.7, 'confidence': 0.7, 'place_info': {'name': '–ú–æ—Å–∫–≤–∞', 'description': '–†–æ—Å—Å–∏—è', 'coordinates': {'latitude': 55.755864, 'longitude': 37.617698}, 'address': '–†–æ—Å—Å–∏—è, –ú–æ—Å–∫–≤–∞', 'category': ['province'], 'phone': [], 'url': '', 'hours': {}, 'precision': 'other', 'type': 'province'}}, 'confidence_score': 0.7, 'sources_used': ['yandex_search'], 'all_results': {'external_apis': {'yandex': {'success': True, 'source': 'yandex_maps', 'query': '–ú–æ—Å–∫–≤–∞', 'total_found': 1, 'places': [{'name': '–ú–æ—Å–∫–≤–∞', 'description': '–†–æ—Å—Å–∏—è', 'coordinates': {'latitude': 55.755864, 'longitude': 37.617698}, 'address': '–†–æ—Å—Å–∏—è, –ú–æ—Å–∫–≤–∞', 'category': ['province'], 'phone': [], 'url': '', 'hours': {}, 'precision': 'other', 'type': 'province'}]}, 'dgis': {'success': False}, 'osm': {'success': False}}}, 'recommendations': ['–°—Ä–µ–¥–Ω—è—è —É–≤–µ—Ä–µ–Ω–Ω–æ—Å—Ç—å –≤ —Ä–µ–∑—É–ª—å—Ç–∞—Ç–µ', '–î–ª—è –ø–æ–≤—ã—à–µ–Ω–∏—è —Ç–æ—á–Ω–æ—Å—Ç–∏ –¥–æ–±–∞–≤—å—Ç–µ –æ–ø–∏—Å–∞–Ω–∏–µ –º–µ—Å—Ç–∞']}
INFO:services.coordinate_detector:  Archive: None
INFO:services.coordinate_detector:  Google OCR: None
INFO:services.coordinate_detector:  Google Geo: None
INFO:services.coordinate_detector:  Similarity: None
INFO:services.coordinate_detector:üìç Final coordinates: {'latitude': 55.755864, 'longitude': 37.617698, 'confidence': 0.7, 'source': 'geolocation_service', 'all_sources': [{'latitude': 55.755864, 'longitude': 37.617698, 'source': 'geolocation_service', 'confidence': 0.7, 'priority': 2}]}
INFO:services.coordinate_detector:üõ∞Ô∏è Getting satellite imagery for coordinates: 55.755864, 37.617698
ERROR:services.roscosmos_satellite_service:Geoportal error: HTTPSConnectionPool(host='catalog.gptl.ru', port=443): Max retries exceeded with url: /api/search?bbox=37.607698%2C55.745864000000005%2C37.627697999999995%2C55.765864&limit=10&cloud_cover=30&api_key=MjYxMTk0MjI3.MjYxMTk0MjQ1.a3d78e3e72-88656c-8eb246 (Caused by NameResolutionError("<urllib3.connection.HTTPSConnection object at 0x78bc306557c0>: Failed to resolve 'catalog.gptl.ru' ([Errno -2] Name or service not known)"))
WARNING:services.roscosmos_satellite_service:ScanEx returned non-image content: b'\xef\xbb\xbf<?xml version="1.0" encoding="utf-8"?>\r\n<Exception>\r\n  <Message>Internal error: APIkey not found<'
WARNING:services.roscosmos_satellite_service:Public source ESRI World Imagery failed: HTTPSConnectionPool(host='server.arcgisonline.com', port=443): Max retries exceeded with url: /ArcGIS/rest/services/World_Imagery/MapServer/tile/16/20486/39616 (Caused by NameResolutionError("<urllib3.connection.HTTPSConnection object at 0x78bc30655fa0>: Failed to resolve 'server.arcgisonline.com' ([Errno -2] Name or service not known)"))
INFO:services.coordinate_detector:‚úÖ Roscosmos satellite image obtained
ERROR:services.yandex_satellite_service:Yandex satellite image error: 403 Client Error: Forbidden for url: https://static-maps.yandex.ru/1.x/?ll=37.617698%2C55.755864&z=16&size=512%2C512&l=sat&apikey=6f97dac1-f67f-4e10-89b8-c43c4dc930f7
INFO:services.coordinate_detector:üó∫Ô∏è Getting enhanced location info for: 55.755864, 37.617698
INFO:services.coordinate_detector:‚úÖ Yandex reverse geocoding successful
INFO:services.coordinate_detector:‚úÖ 2GIS found 0 nearby places
INFO:services.coordinate_detector:‚úÖ Yandex location search successful
INFO:routes.coordinate_api:Coordinate detection result: success=True, coordinates=True
INFO:routes.coordinate_api:API response: success=True, message='Detected 5 objects'
INFO:werkzeug:127.0.0.1 - - [11/Sep/2025 17:39:26] "POST /api/coordinates/detect HTTP/1.1" 200 -
INFO:werkzeug:127.0.0.1 - - [11/Sep/2025 17:41:04] "OPTIONS /api/coordinates/video/estimate HTTP/1.1" 200 -
INFO:werkzeug:127.0.0.1 - - [11/Sep/2025 17:41:04] "POST /api/coordinates/video/estimate HTTP/1.1" 200 -
